<?xml version="1.0" ?>
<!-- =================================================================================== -->
<!-- |    This document was autogenerated by xacro from rv7f.urdf.xacro                | -->
<!-- |    EDITING THIS FILE BY HAND IS NOT RECOMMENDED                                 | -->
<!-- =================================================================================== -->
<robot name="rv7f" xmlns:xacro="http://ros.org/wiki/xacro">
  <!-- Include -->
  <material name="black">
    <color rgba="0.0 0.0 0.0 1.0"/>
  </material>
  <material name="blue">
    <color rgba="0.0 0.0 0.8 1.0"/>
  </material>
  <material name="green">
    <color rgba="0.0 0.8 0.0 1.0"/>
  </material>
  <material name="grey">
    <color rgba="0.2 0.2 0.2 1.0"/>
  </material>
  <material name="orange">
    <color rgba="1.0 0.423529411765 0.0392156862745 1.0"/>
  </material>
  <material name="brown">
    <color rgba="0.870588235294 0.811764705882 0.764705882353 1.0"/>
  </material>
  <material name="red">
    <color rgba="0.8 0.0 0.0 1.0"/>
  </material>
  <material name="white">
    <color rgba="1.0 1.0 1.0 1.0"/>
  </material>
  <!-- Radius Limits -->
  <!-- Velocity Limits -->
  <link name="base_link">
    <visual>
      <geometry>
        <mesh filename="package://mitsubishi_rv7f_description/meshes/rv7f/visual/base_link.dae"/>
      </geometry>
    </visual>
    <collision>
      <geometry>
        <mesh filename="package://mitsubishi_rv7f_description/meshes/rv7f/collision/base_link.stl"/>
      </geometry>
    </collision>
    <inertial>
      <mass value="12.928376"/>
      <inertia ixx="0.259755" ixy="-0.000334" ixz="-0.032452" iyy="0.287122" iyz="-0.023950" izz="0.148846"/>
    </inertial>
  </link>
  <link name="world"/>
  <joint name="world" type="fixed">
    <parent link="world"/>
    <child link="base_link"/>
  </joint>
  <link name="link_1">
    <visual>
      <geometry>
        <mesh filename="package://mitsubishi_rv7f_description/meshes/rv7f/visual/link_1.dae"/>
      </geometry>
    </visual>
    <collision>
      <geometry>
        <mesh filename="package://mitsubishi_rv7f_description/meshes/rv7f/collision/link_1.stl"/>
      </geometry>
    </collision>
    <inertial>
      <mass value="5.855081"/>
      <inertia ixx="0.109940" ixy="-0.000021" ixz="-0.001942" iyy="0.071902" iyz="-0.000051" izz="0.065726"/>
    </inertial>
  </link>
  <joint name="J1" type="revolute">
    <origin rpy="0 0 0" xyz="0 0 0.3995"/>
    <parent link="base_link"/>
    <child link="link_1"/>
    <axis xyz="0 0 1"/>
    <dynamics dampint="0.7" friction="0.7"/>
    <limit effort="30.0" lower="-4.18879032" upper="4.18879032" velocity="6.28318548"/>
  </joint>
  <link name="link_2">
    <visual>
      <geometry>
        <mesh filename="package://mitsubishi_rv7f_description/meshes/rv7f/visual/link_2.dae"/>
      </geometry>
    </visual>
    <collision>
      <geometry>
        <mesh filename="package://mitsubishi_rv7f_description/meshes/rv7f/collision/link_2.stl"/>
      </geometry>
    </collision>
    <inertial>
      <mass value="9.260846"/>
      <inertia ixx="0.295810" ixy="-0.000221" ixz="-0.019796" iyy="0.282036" iyz="0.001444" izz="0.053750"/>
    </inertial>
  </link>
  <joint name="J2" type="revolute">
    <origin rpy="0 0 0" xyz="0 0 0"/>
    <parent link="link_1"/>
    <child link="link_2"/>
    <axis xyz="0 1 0"/>
    <dynamics dampint="0.7" friction="0.7"/>
    <limit effort="30.0" lower="-2.007128695" upper="2.181661625" velocity="6.998770493"/>
  </joint>
  <link name="link_3">
    <visual>
      <geometry>
        <mesh filename="package://mitsubishi_rv7f_description/meshes/rv7f/visual/link_3.dae"/>
      </geometry>
    </visual>
    <collision>
      <geometry>
        <mesh filename="package://mitsubishi_rv7f_description/meshes/rv7f/collision/link_3.stl"/>
      </geometry>
    </collision>
    <inertial>
      <mass value="3.795239"/>
      <inertia ixx="0.014442" ixy="0.000207" ixz="0.001511" iyy="0.017521" iyz="0.000026" izz="0.014809"/>
    </inertial>
  </link>
  <joint name="J3" type="revolute">
    <origin rpy="0 0 0" xyz="0 0 0.340"/>
    <parent link="link_2"/>
    <child link="link_3"/>
    <axis xyz="0 1 0"/>
    <dynamics dampint="0.7" friction="0.7"/>
    <limit effort="30.0" lower="-1.57079635255" upper="1.151917338" velocity="7.85398185"/>
  </joint>
  <link name="link_4">
    <visual>
      <geometry>
        <mesh filename="package://mitsubishi_rv7f_description/meshes/rv7f/visual/link_4.dae"/>
      </geometry>
    </visual>
    <collision>
      <geometry>
        <mesh filename="package://mitsubishi_rv7f_description/meshes/rv7f/collision/link_4.stl"/>
      </geometry>
    </collision>
    <inertial>
      <mass value="2.764278"/>
      <inertia ixx="0.005405" ixy="-0.000329" ixz="0.000192" iyy="0.080630" iyz="0.000000" izz="0.081901"/>
    </inertial>
  </link>
  <joint name="J4" type="revolute">
    <origin rpy="0 0 0" xyz="0.37 0 0.05"/>
    <parent link="link_3"/>
    <child link="link_4"/>
    <axis xyz="1 0 0"/>
    <dynamics dampint="0.7" friction="0.7"/>
    <limit effort="30.0" lower="-3.4906586" upper="3.4906586" velocity="5.881759741"/>
  </joint>
  <link name="link_5">
    <visual>
      <geometry>
        <mesh filename="package://mitsubishi_rv7f_description/meshes/rv7f/visual/link_5.dae"/>
      </geometry>
    </visual>
    <collision>
      <geometry>
        <mesh filename="package://mitsubishi_rv7f_description/meshes/rv7f/collision/link_5.stl"/>
      </geometry>
    </collision>
    <inertial>
      <mass value="0.5803"/>
      <inertia ixx="0.000519" ixy="0.000000" ixz="0.000026" iyy="0.000937" iyz="0.000000" izz="0.000827"/>
    </inertial>
  </link>
  <joint name="J5" type="revolute">
    <origin rpy="0 0 0" xyz="0 0 0"/>
    <parent link="link_4"/>
    <child link="link_5"/>
    <axis xyz="0 1 0"/>
    <dynamics dampint="0.7" friction="0.7"/>
    <limit effort="30.0" lower="-2.09439516" upper="2.09439516" velocity="7.85398185"/>
  </joint>
  <link name="link_6">
    <visual>
      <geometry>
        <mesh filename="package://mitsubishi_rv7f_description/meshes/rv7f/visual/link_6.dae"/>
      </geometry>
    </visual>
    <collision>
      <geometry>
        <mesh filename="package://mitsubishi_rv7f_description/meshes/rv7f/collision/link_6.stl"/>
      </geometry>
    </collision>
    <inertial>
      <mass value="0.025371"/>
      <inertia ixx="0.000011" ixy="0.000000" ixz="0.000000" iyy="0.000006" iyz="0.000000" izz="0.000007"/>
    </inertial>
  </link>
  <joint name="J6" type="revolute">
    <origin rpy="0 0 0" xyz="0.0713 0 0"/>
    <parent link="link_5"/>
    <child link="link_6"/>
    <axis xyz="1 0 0"/>
    <dynamics dampint="0.7" friction="0.7"/>
    <limit effort="30.0" lower="-3.4906586" upper="3.4906586" velocity="12.56637096"/>
  </joint>
  <!--   <joint name="joint_tool0" type="fixed">
    <origin rpy="0 0 0" xyz="0 0 0"/>
    <parent link="link_6"/>
    <child link="tool0"/>
  </joint>
 -->
  <!-- transmission -->
  <transmission name="transmission_1">
    <type>transmission_interface/SimpleTransmission</type>
    <joint name="J1">
      <hardwareInterface>PositionJointInterface</hardwareInterface>
    </joint>
    <actuator name="motor_1">
      <hardwareInterface>PositionJointInterface</hardwareInterface>
      <mechanicalReduction>1</mechanicalReduction>
    </actuator>
  </transmission>
  <transmission name="transmission_2">
    <type>transmission_interface/SimpleTransmission</type>
    <joint name="J2">
      <hardwareInterface>PositionJointInterface</hardwareInterface>
    </joint>
    <actuator name="motor_2">
      <hardwareInterface>PositionJointInterface</hardwareInterface>
      <mechanicalReduction>1</mechanicalReduction>
    </actuator>
  </transmission>
  <transmission name="transmission_3">
    <type>transmission_interface/SimpleTransmission</type>
    <joint name="J3">
      <hardwareInterface>PositionJointInterface</hardwareInterface>
    </joint>
    <actuator name="motor_3">
      <hardwareInterface>PositionJointInterface</hardwareInterface>
      <mechanicalReduction>1</mechanicalReduction>
    </actuator>
  </transmission>
  <transmission name="transmission_4">
    <type>transmission_interface/SimpleTransmission</type>
    <joint name="J4">
      <hardwareInterface>PositionJointInterface</hardwareInterface>
    </joint>
    <actuator name="motor_4">
      <hardwareInterface>PositionJointInterface</hardwareInterface>
      <mechanicalReduction>1</mechanicalReduction>
    </actuator>
  </transmission>
  <transmission name="transmission_5">
    <type>transmission_interface/SimpleTransmission</type>
    <joint name="J5">
      <hardwareInterface>PositionJointInterface</hardwareInterface>
    </joint>
    <actuator name="motor_5">
      <hardwareInterface>PositionJointInterface</hardwareInterface>
      <mechanicalReduction>1</mechanicalReduction>
    </actuator>
  </transmission>
  <transmission name="transmission_6">
    <type>transmission_interface/SimpleTransmission</type>
    <joint name="J6">
      <hardwareInterface>PositionJointInterface</hardwareInterface>
    </joint>
    <actuator name="motor_6">
      <hardwareInterface>PositionJointInterface</hardwareInterface>
      <mechanicalReduction>1</mechanicalReduction>
    </actuator>
  </transmission>
  <!-- gazebo -->
  <gazebo>
    <plugin filename="libgazebo_ros_control.so" name="gazebo_ros_control">
      <robotNamespace>/rv7f</robotNamespace>
      <robotSimType>gazebo_ros_control/DefaultRobotHWSim</robotSimType>
    </plugin>
  </gazebo>
  <gazebo reference="base_link">
    <mu1>0.2</mu1>
    <mu2>0.2</mu2>
    <selfCollide>true</selfCollide>
  </gazebo>
  <gazebo reference="link_1">
    <mu1>0.2</mu1>
    <mu2>0.2</mu2>
    <selfCollide>true</selfCollide>
  </gazebo>
  <gazebo reference="link_2">
    <mu1>0.2</mu1>
    <mu2>0.2</mu2>
    <selfCollide>true</selfCollide>
  </gazebo>
  <gazebo reference="link_3">
    <mu1>0.2</mu1>
    <mu2>0.2</mu2>
    <selfCollide>true</selfCollide>
  </gazebo>
  <gazebo reference="link_4">
    <mu1>0.2</mu1>
    <mu2>0.2</mu2>
    <selfCollide>true</selfCollide>
  </gazebo>
  <gazebo reference="link_5">
    <mu1>0.2</mu1>
    <mu2>0.2</mu2>
    <selfCollide>true</selfCollide>
  </gazebo>
  <gazebo reference="link_6">
    <mu1>0.2</mu1>
    <mu2>0.2</mu2>
    <selfCollide>true</selfCollide>
  </gazebo>
</robot>

