<?xml version="1.0"?>
<robot xmlns:xacro="http://ros.org/wiki/xacro">
  <xacro:macro name="base_link_v1" params="name mass *inertia">
    <link name="${name}">
      <visual>
        <geometry>
          <mesh filename="package://mitsubishi_rv7f_description/meshes/rv7f/visual/${name}.dae"/>
        </geometry>
      </visual>
      <collision>
        <geometry>
          <mesh filename="package://mitsubishi_rv7f_description/meshes/rv7f/collision/${name}.stl"/>
        </geometry>
      </collision>
      <inertial>
        <mass value="${mass}"/>
        <insert_block name="inertia"/>
      </inertial>
    </link>

  <link name="world"/>
  <joint name="world" type="fixed">
    <parent link="world"/>
    <child link="${name}"/>
  </joint>
  </xacro:macro>


  <xacro:macro name="link_v1" params="name mass parent_link_name child_link_name joint_name *inertia *joint_origin *joint_axis *joint_limit">
    <link name="${name}">
      <visual>
        <geometry>
          <mesh filename="package://mitsubishi_rv7f_description/meshes/rv7f/visual/${name}.dae"/>
        </geometry>
      </visual>
      <collision>
        <geometry>
          <mesh filename="package://mitsubishi_rv7f_description/meshes/rv7f/collision/${name}.stl"/>
        </geometry>
      </collision>
      <inertial>
        <mass value="${mass}"/>
        <insert_block name="inertia"/>
      </inertial>
    </link>

    <joint name="${joint_name}" type="revolute">
      <insert_block name="joint_origin"/>
      <parent link="${parent_link_name}"/>
      <child link="${child_link_name}"/>
      <insert_block name="joint_axis"/>
      <dynamics dampint="0.7" friction="0.7"/>
      <insert_block name="joint_limit"/>
    </joint>
  </xacro:macro>
</robot>